<?xml version="1.0"?>
<robot  name="busybox" >
 <link  name="base_link" >
  <inertial >
   <origin  rpy="0 0 0"  xyz="0 0 0" />
   <mass  value="0" />
   <inertia  ixz="0"  iyz="0"  ixy="0"  ixx="0.001"  izz="0.001"  iyy="0.001" />
  </inertial>
  <collision >
   <origin  rpy="0 0 0"  xyz="0 0 0" />
   <geometry >
    <box  size="0.6 0.3 0.1" />
   </geometry>
  </collision>
  <visual >
   <origin  rpy="0 0 0"  xyz="0 0 0" />
   <geometry >
    <box  size="0.6 0.3 0.1" />
   </geometry>
   <material  name="brown" >
    <color  rgba="0.82 0.71 0.55 1.0" />
   </material>
  </visual>
 </link>
 <link  name="back_link" >
  <inertial >
   <origin  rpy="0 0 0"  xyz="0 0 0" />
   <mass  value="0.5" />
   <inertia  ixz="0"  iyz="0"  ixy="0"  ixx="0.001"  izz="0.001"  iyy="0.001" />
  </inertial>
  <collision >
   <origin  rpy="0 0 0"  xyz="0 0 0" />
   <geometry >
    <box  size="0.6 0.05 0.6" />
   </geometry>
  </collision>
  <visual >
   <origin  rpy="0 0 0"  xyz="0 0 0" />
   <geometry >
    <box  size="0.6 0.05 0.6" />
   </geometry>
   <material  name="brown" >
    <color  rgba="0.82 0.71 0.55 1.0" />
   </material>
  </visual>
 </link>
 <joint  name="fixed_backboard"  type="fixed" >
  <parent  link="base_link" />
  <child  link="back_link" />
  <origin  rpy="0 0 0"  xyz="0 0 0.35" />
 </joint>
 <link  name="slider_13_handle" >
  <inertial >
   <origin  rpy="0 0 0"  xyz="0 0 0" />
   <mass  value="0.1" />
   <inertia  ixz="0"  iyz="0"  ixy="0"  ixx="0.001"  izz="0.001"  iyy="0.001" />
  </inertial>
  <collision >
   <origin  rpy="0 0 0"  xyz="0 0 0" />
   <geometry >
    <cylinder  radius="0.02"  length="0.05" />
   </geometry>
  </collision>
  <visual >
   <origin  rpy="0 0 0"  xyz="0 0 0" />
   <geometry >
    <cylinder  radius="0.02"  length="0.05" />
   </geometry>
   <material  name="slider_13_color" >
    <color  rgba="1.0 0.0 0.0 1.0" />
   </material>
  </visual>
 </link>
 <link  name="slider_13_track" >
  <inertial >
   <origin  rpy="0 0 0"  xyz="0 0 0" />
   <mass  value="0.1" />
   <inertia  ixz="0"  iyz="0"  ixy="0"  ixx="0.001"  izz="0.001"  iyy="0.001" />
  </inertial>
  <collision >
   <origin  rpy="0 0 0"  xyz="0 0 0" />
   <geometry >
    <box  size="0.4959613416395672 0.005 0.02" />
   </geometry>
  </collision>
  <visual >
   <origin  rpy="0 0 0"  xyz="0 0 0" />
   <geometry >
    <box  size="0.4959613416395672 0.005 0.02" />
   </geometry>
   <material  name="slider_track_color" >
    <color  rgba="0.6 0.6 0.6 1.0" />
   </material>
  </visual>
 </link>
 <joint  name="slider_13_joint"  type="prismatic" >
  <parent  link="back_link" />
  <child  link="slider_13_handle" />
  <axis  xyz="-0.9488228370213238 0.31580884083066213 0" />
  <origin  rpy="1.57 0 0"  xyz="-0.0318636095201309 0.05 -0.15412396644716406" />
  <limit  lower="-0.2479806708197836"  upper="0.2479806708197836"  effort="UNNAMED_10"  velocity="UNNAMED_11" />
  <dynamics  damping="1.0"  friction="1.0" />
 </joint>
 <joint  name="slider_13_track_joint"  type="fixed" >
  <parent  link="back_link" />
  <child  link="slider_13_track" />
  <origin  rpy="0 -2.8202836526317685 0"  xyz="-0.0318636095201309 0.025 -0.15412396644716406" />
 </joint>
</robot>
