<?xml version="1.0"?>
<robot  name="busybox" >
 <link  name="base_link" >
  <inertial >
   <origin  xyz="0 0 0"  rpy="0 0 0" />
   <mass  value="0" />
   <inertia  izz="0.001"  iyz="0"  ixz="0"  ixx="0.001"  iyy="0.001"  ixy="0" />
  </inertial>
  <collision >
   <origin  xyz="0 0 0"  rpy="0 0 0" />
   <geometry >
    <box  size="0.6 0.3 0.1" />
   </geometry>
  </collision>
  <visual >
   <origin  xyz="0 0 0"  rpy="0 0 0" />
   <geometry >
    <box  size="0.6 0.3 0.1" />
   </geometry>
   <material  name="brown" >
    <color  rgba="0.82 0.71 0.55 1.0" />
   </material>
  </visual>
 </link>
 <link  name="back_link" >
  <inertial >
   <origin  xyz="0 0 0"  rpy="0 0 0" />
   <mass  value="0.5" />
   <inertia  izz="0.001"  iyz="0"  ixz="0"  ixx="0.001"  iyy="0.001"  ixy="0" />
  </inertial>
  <collision >
   <origin  xyz="0 0 0"  rpy="0 0 0" />
   <geometry >
    <box  size="0.6 0.05 0.6" />
   </geometry>
  </collision>
  <visual >
   <origin  xyz="0 0 0"  rpy="0 0 0" />
   <geometry >
    <box  size="0.6 0.05 0.6" />
   </geometry>
   <material  name="brown" >
    <color  rgba="0.82 0.71 0.55 1.0" />
   </material>
  </visual>
 </link>
 <joint  type="fixed"  name="fixed_backboard" >
  <parent  link="base_link" />
  <child  link="back_link" />
  <origin  xyz="0 0 0.35"  rpy="0 0 0" />
 </joint>
 <link  name="slider_2_handle" >
  <inertial >
   <origin  xyz="0 0 0"  rpy="0 0 0" />
   <mass  value="0.1" />
   <inertia  izz="0.001"  iyz="0"  ixz="0"  ixx="0.001"  iyy="0.001"  ixy="0" />
  </inertial>
  <collision >
   <origin  xyz="0 0 0"  rpy="0 0 0" />
   <geometry >
    <cylinder  radius="0.02"  length="0.05" />
   </geometry>
  </collision>
  <visual >
   <origin  xyz="0 0 0"  rpy="0 0 0" />
   <geometry >
    <cylinder  radius="0.02"  length="0.05" />
   </geometry>
   <material  name="slider_2_color" >
    <color  rgba="1.0 0.0 0.0 1.0" />
   </material>
  </visual>
 </link>
 <link  name="slider_2_track" >
  <inertial >
   <origin  xyz="0 0 0"  rpy="0 0 0" />
   <mass  value="0.1" />
   <inertia  izz="0.001"  iyz="0"  ixz="0"  ixx="0.001"  iyy="0.001"  ixy="0" />
  </inertial>
  <collision >
   <origin  xyz="0 0 0"  rpy="0 0 0" />
   <geometry >
    <box  size="0.10743110160895926 0.005 0.02" />
   </geometry>
  </collision>
  <visual >
   <origin  xyz="0 0 0"  rpy="0 0 0" />
   <geometry >
    <box  size="0.10743110160895926 0.005 0.02" />
   </geometry>
   <material  name="slider_track_color" >
    <color  rgba="0.6 0.6 0.6 1.0" />
   </material>
  </visual>
 </link>
 <joint  type="prismatic"  name="slider_2_joint" >
  <parent  link="back_link" />
  <child  link="slider_2_handle" />
  <axis  xyz="-0.45640013771751753 0.8897746424187594 0" />
  <origin  xyz="0.011738085164543666 0.05 0.024457010836680226"  rpy="1.57 0 0" />
  <limit  lower="-0.05371555080447963"  upper="0.05371555080447963"  velocity="UNNAMED_2"  effort="UNNAMED_3" />
  <dynamics  damping="1.0"  friction="1.0" />
 </joint>
 <joint  type="fixed"  name="slider_2_track_joint" >
  <parent  link="back_link" />
  <child  link="slider_2_track" />
  <origin  xyz="0.011738085164543666 0.025 0.024457010836680226"  rpy="0 -2.044741493916277 0" />
 </joint>
</robot>
