<?xml version="1.0"?>
<robot  name="busybox" >
 <link  name="base_link" >
  <inertial >
   <origin  xyz="0 0 0"  rpy="0 0 0" />
   <mass  value="0" />
   <inertia  ixy="0"  iyy="0.001"  ixx="0.001"  iyz="0"  ixz="0"  izz="0.001" />
  </inertial>
  <collision >
   <origin  xyz="0 0 0"  rpy="0 0 0" />
   <geometry >
    <box  size="0.6 0.3 0.1" />
   </geometry>
  </collision>
  <visual >
   <origin  xyz="0 0 0"  rpy="0 0 0" />
   <geometry >
    <box  size="0.6 0.3 0.1" />
   </geometry>
   <material  name="brown" >
    <color  rgba="0.82 0.71 0.55 1.0" />
   </material>
  </visual>
 </link>
 <link  name="back_link" >
  <inertial >
   <origin  xyz="0 0 0"  rpy="0 0 0" />
   <mass  value="0.5" />
   <inertia  ixy="0"  iyy="0.001"  ixx="0.001"  iyz="0"  ixz="0"  izz="0.001" />
  </inertial>
  <collision >
   <origin  xyz="0 0 0"  rpy="0 0 0" />
   <geometry >
    <box  size="0.6 0.05 0.6" />
   </geometry>
  </collision>
  <visual >
   <origin  xyz="0 0 0"  rpy="0 0 0" />
   <geometry >
    <box  size="0.6 0.05 0.6" />
   </geometry>
   <material  name="brown" >
    <color  rgba="0.82 0.71 0.55 1.0" />
   </material>
  </visual>
 </link>
 <joint  name="fixed_backboard"  type="fixed" >
  <parent  link="base_link" />
  <child  link="back_link" />
  <origin  xyz="0 0 0.35"  rpy="0 0 0" />
 </joint>
 <link  name="slider_72_handle" >
  <inertial >
   <origin  xyz="0 0 0"  rpy="0 0 0" />
   <mass  value="0.1" />
   <inertia  ixy="0"  iyy="0.001"  ixx="0.001"  iyz="0"  ixz="0"  izz="0.001" />
  </inertial>
  <collision >
   <origin  xyz="0 0 0"  rpy="0 0 0" />
   <geometry >
    <cylinder  radius="0.02"  length="0.05" />
   </geometry>
  </collision>
  <visual >
   <origin  xyz="0 0 0"  rpy="0 0 0" />
   <geometry >
    <cylinder  radius="0.02"  length="0.05" />
   </geometry>
   <material  name="slider_72_color" >
    <color  rgba="1.0 0.0 0.0 1.0" />
   </material>
  </visual>
 </link>
 <link  name="slider_72_track" >
  <inertial >
   <origin  xyz="0 0 0"  rpy="0 0 0" />
   <mass  value="0.1" />
   <inertia  ixy="0"  iyy="0.001"  ixx="0.001"  iyz="0"  ixz="0"  izz="0.001" />
  </inertial>
  <collision >
   <origin  xyz="0 0 0"  rpy="0 0 0" />
   <geometry >
    <box  size="0.3203024813295854 0.005 0.02" />
   </geometry>
  </collision>
  <visual >
   <origin  xyz="0 0 0"  rpy="0 0 0" />
   <geometry >
    <box  size="0.3203024813295854 0.005 0.02" />
   </geometry>
   <material  name="slider_track_color" >
    <color  rgba="0.6 0.6 0.6 1.0" />
   </material>
  </visual>
 </link>
 <joint  name="slider_72_joint"  type="prismatic" >
  <parent  link="back_link" />
  <child  link="slider_72_handle" />
  <axis  xyz="-0.7010127802428574 0.7131487095523481 0" />
  <origin  xyz="0.0396377531083687 0.05 0.0327181465653521"  rpy="1.57 0 0" />
  <limit  lower="-0.1601512406647927"  upper="0.1601512406647927"  effort="UNNAMED_78"  velocity="UNNAMED_79" />
  <dynamics  damping="1.0"  friction="1.0" />
 </joint>
 <joint  name="slider_72_track_joint"  type="fixed" >
  <parent  link="back_link" />
  <child  link="slider_72_track" />
  <origin  xyz="0.0396377531083687 0.025 0.0327181465653521"  rpy="0 -2.3476129869551983 0" />
 </joint>
</robot>
